Workbook
Name Slicer_Beverage_Brand: #N/A

Sheet pivots
A3: Row Labels | B3: Sum of Total Sales
A4: Costco | B4: 1291535
A5: CVS | B5: 2115587.5
A6: Target | B6: 404412.5
A7: Walmart | B7: 4403630
A8: Grand Total | B8: 8215165
N9: Sum of Total Sales | O9: Sum of Units Sold | P9: Sum of Operating Profit
N10: 8215165 | O10: 16482500 | P10: 3041141.9
A19: Row Labels | B19: Sum of Total Sales | C19: Sum of Operating Profit | D19: Sum of Units Sold | G19: States | H19: =B19 -> Sum of Total Sales | I19: =C19 -> Sum of Operating Profit | J19: =D19 -> Sum of Units Sold
A20: New York | B20: 582675 | C20: 203082.5 | D20: 1125200 | G20: =A20 -> New York | H20: =B20 -> 582675 | I20: =C20 -> 203082.5 | J20: =D20 -> 1125200
A21: California | B21: 582400 | C21: 183895.62 | D21: 1037250 | G21: =A21 -> California | H21: =B21 -> 582400 | I21: =C21 -> 183895.62 | J21: =D21 -> 1037250
A22: Florida | B22: 561850 | C22: 214731.25 | D22: 1051700 | G22: =A22 -> Florida | H22: =B22 -> 561850 | I22: =C22 -> 214731.25 | J22: =D22 -> 1051700
A23: Texas | B23: 440987.5 | C23: 176324.38 | D23: 1014250 | G23: =A23 -> Texas | H23: =B23 -> 440987.5 | I23: =C23 -> 176324.38 | J23: =D23 -> 1014250
A24: Georgia | B24: 292210 | C24: 111621.5 | D24: 579350 | G24: =A24 -> Georgia | H24: =B24 -> 292210 | I24: =C24 -> 111621.5 | J24: =D24 -> 579350
A25: Washington | B25: 250237.5 | C25: 64440.625 | D25: 348750 | G25: =A25 -> Washington | H25: =B25 -> 250237.5 | I25: =C25 -> 64440.625 | J25: =D25 -> 348750
A26: South Carolina | B26: 238055 | C26: 96130.125 | D26: 507350 | G26: =A26 -> South Carolina | H26: =B26 -> 238055 | I26: =C26 -> 96130.125 | J26: =D26 -> 507350
A27: Oregon | B27: 226300 | C27: 89835 | D27: 346750 | G27: =A27 -> Oregon | H27: =B27 -> 226300 | I27: =C27 -> 89835 | J27: =D27 -> 346750
A28: Colorado | B28: 202725 | C28: 74185.625 | D28: 324250 | G28: =A28 -> Colorado | H28: =B28 -> 202725 | I28: =C28 -> 74185.625 | J28: =D28 -> 324250
A29: Utah | B29: 199937.5 | C29: 69359.375 | D29: 310750 | G29: =A29 -> Utah | H29: =B29 -> 199937.5 | I29: =C29 -> 69359.375 | J29: =D29 -> 310750
A30: Grand Total | B30: 3577377.5 | C30: 1283606 | D30: 6645600
A37: Row Labels | B37: Sum of Units Sold
A38: Jan | B38: 1305750
A39: Feb | B39: 1232250
A40: Mar | B40: 1162250
A41: Apr | B41: 1135250
A42: May | B42: 1307500
A43: Jun | B43: 1550750
A44: Jul | B44: 1683500
A45: Aug | B45: 1583000
A46: Sep | B46: 1330750
A47: Oct | B47: 1207500
A48: Nov | B48: 1380000
A49: Dec | B49: 1604000
A50: Grand Total | B50: 16482500
A56: State | B56: Region | C56: Sum of Total Sales | F56: =B56 -> Region | G56: =C56 -> Sum of Total Sales | H56: =C56 -> Sum of Total Sales
A57: Alabama | B57: South | C57: 170562.5 | F57: =A57 -> Alabama | G57: =C57 -> 170562.5 | H57: =C57 -> 170562.5
A58: Arizona | B58: West | C58: 192137.5 | F58: =A58 -> Arizona | G58: =C58 -> 192137.5 | H58: =C58 -> 192137.5
A59: Arkansas | B59: South | C59: 101732.5 | F59: =A59 -> Arkansas | G59: =C59 -> 101732.5 | H59: =C59 -> 101732.5
A60: California | B60: West | C60: 582400 | F60: =A60 -> California | G60: =C60 -> 582400 | H60: =C60 -> 582400
A61: Colorado | B61: West | C61: 202725 | F61: =A61 -> Colorado | G61: =C61 -> 202725 | H61: =C61 -> 202725
...

Sheet Data
A1: Retailer | B1: Retailer ID | C1: Invoice Date | D1: Region | E1: State | F1: City | G1: Beverage Brand | H1: Days to Deliver | I1: Delivery Company | J1: Price per Unit | K1: Units Sold | L1: Total Sales | M1: Operating Profit | N1: Operating Margin
A2: Walmart | B2: 1185732 | C2: 44575 | D2: Northeast | E2: New York | F2: New York | G2: Coca-Cola | H2: 25 | I2: USPS | J2: 0.5 | K2: 12000 | L2: =J2*K2 -> 6000 | M2: =L2*N2 -> 3000 | N2: 0.5
A3: Walmart | B3: 1185732 | C3: 44575 | D3: Northeast | E3: New York | F3: New York | G3: Diet Coke | H3: 34 | I3: FedEx | J3: 0.5 | K3: 10000 | L3: =J3*K3 -> 5000 | M3: =L3*N3 -> 1500 | N3: 0.3
A4: Walmart | B4: 1185732 | C4: 44575 | D4: Northeast | E4: New York | F4: New York | G4: Sprite | H4: 48 | I4: UPS | J4: 0.4 | K4: 10000 | L4: =J4*K4 -> 4000 | M4: =L4*N4 -> 1400 | N4: 0.35
A5: Walmart | B5: 1185732 | C5: 44575 | D5: Northeast | E5: New York | F5: New York | G5: Fanta | H5: 20 | I5: USPS | J5: 0.45 | K5: 8500 | L5: =J5*K5 -> 3825 | M5: =L5*N5 -> 1338.75 | N5: 0.35
A6: Walmart | B6: 1185732 | C6: 44575 | D6: Northeast | E6: New York | F6: New York | G6: Powerade | H6: 26 | I6: USPS | J6: 0.6 | K6: 9000 | L6: =J6*K6 -> 5400 | M6: =L6*N6 -> 1620 | N6: 0.3
A7: Walmart | B7: 1185732 | C7: 44575 | D7: Northeast | E7: New York | F7: New York | G7: Dasani Water | H7: 43 | I7: DHL | J7: 0.5 | K7: 10000 | L7: =J7*K7 -> 5000 | M7: =L7*N7 -> 1250 | N7: 0.25
A8: Walmart | B8: 1185732 | C8: 44604 | D8: Northeast | E8: New York | F8: New York | G8: Coca-Cola | H8: 19 | I8: FedEx | J8: 0.5 | K8: 12500 | L8: =J8*K8 -> 6250 | M8: =L8*N8 -> 3125 | N8: 0.5
A9: Walmart | B9: 1185732 | C9: 44604 | D9: Northeast | E9: New York | F9: New York | G9: Diet Coke | H9: 41 | I9: FedEx | J9: 0.5 | K9: 9000 | L9: =J9*K9 -> 4500 | M9: =L9*N9 -> 1350 | N9: 0.3
A10: Walmart | B10: 1185732 | C10: 44604 | D10: Northeast | E10: New York | F10: New York | G10: Sprite | H10: 34 | I10: USPS | J10: 0.4 | K10: 9500 | L10: =J10*K10 -> 3800 | M10: =L10*N10 -> 1330 | N10: 0.35
A11: Walmart | B11: 1185732 | C11: 44604 | D11: Northeast | E11: New York | F11: New York | G11: Fanta | H11: 42 | I11: UPS | J11: 0.45 | K11: 8250 | L11: =J11*K11 -> 3712.5 | M11: =L11*N11 -> 1299.375 | N11: 0.35
A12: Walmart | B12: 1185732 | C12: 44604 | D12: Northeast | E12: New York | F12: New York | G12: Powerade | H12: 37 | I12: UPS | J12: 0.6 | K12: 9000 | L12: =J12*K12 -> 5400 | M12: =L12*N12 -> 1620 | N12: 0.3
A13: Walmart | B13: 1185732 | C13: 44604 | D13: Northeast | E13: New York | F13: New York | G13: Dasani Water | H13: 59 | I13: UPS | J13: 0.5 | K13: 10000 | L13: =J13*K13 -> 5000 | M13: =L13*N13 -> 1250 | N13: 0.25
... A3745: Walmart | B3745: 1185732 | C3745: 44915 | D3745: Northeast | E3745: New Hampshire | F3745: Manchester | G3745: Dasani Water | H3745: 15 | I3745: FedEx | J3745: 0.8 | K3745: 4250 | L3745: =J3745*K3745 -> 3400 | M3745: =L3745*N3745 -> 1020 | N3745: 0.3

Sheet dashboard
J4: =pivots!G19 -> States | K4: =pivots!H19 -> Sum of Total Sales | L4: =pivots!I19 -> Sum of Operating Profit | M4: =pivots!J19 -> Sum of Units Sold
J5: =pivots!G20 -> New York | K5: =pivots!H20 -> 582675 | L5: =pivots!I20 -> 203082.5 | M5: =pivots!J20 -> 1125200
J6: =pivots!G21 -> California | K6: =pivots!H21 -> 582400 | L6: =pivots!I21 -> 183895.62 | M6: =pivots!J21 -> 1037250
J7: =pivots!G22 -> Florida | K7: =pivots!H22 -> 561850 | L7: =pivots!I22 -> 214731.25 | M7: =pivots!J22 -> 1051700
J8: =pivots!G23 -> Texas | K8: =pivots!H23 -> 440987.5 | L8: =pivots!I23 -> 176324.38 | M8: =pivots!J23 -> 1014250
J9: =pivots!G24 -> Georgia | K9: =pivots!H24 -> 292210 | L9: =pivots!I24 -> 111621.5 | M9: =pivots!J24 -> 579350
J10: =pivots!G25 -> Washington | K10: =pivots!H25 -> 250237.5 | L10: =pivots!I25 -> 64440.625 | M10: =pivots!J25 -> 348750
J11: =pivots!G26 -> South Carolina | K11: =pivots!H26 -> 238055 | L11: =pivots!I26 -> 96130.125 | M11: =pivots!J26 -> 507350
J12: =pivots!G27 -> Oregon | K12: =pivots!H27 -> 226300 | L12: =pivots!I27 -> 89835 | M12: =pivots!J27 -> 346750
J13: =pivots!G28 -> Colorado | K13: =pivots!H28 -> 202725 | L13: =pivots!I28 -> 74185.625 | M13: =pivots!J28 -> 324250
J14: =pivots!G29 -> Utah | K14: =pivots!H29 -> 199937.5 | L14: =pivots!I29 -> 69359.375 | M14: =pivots!J29 -> 310750
